Workbook
Name AbilityPot: 'DMG Calc'!$G$9
Name ElementalPot: 'DMG Calc'!$G$12
Name HighwindCC: 'DMG Calc'!$B$5
Name Int.Arcanum: 'DMG Calc'!$B$27
Name Int.Mastery: 'DMG Calc'!$B$26
Name MemoriaAbilityPots: 'DMG Calc'!$B$21
Name MemoriaElePot: 'DMG Calc'!$B$19
Name MemoriaSpeciesPot: 'DMG Calc'!$B$22
Name OutfitboostAllAllies: 'DMG Calc'!$B$17
Name OutfitPot: 'DMG Calc'!$G$14
Name PATKMATK: 'DMG Calc'!$B$3
Name PhysMagAbilityPot: 'DMG Calc'!$G$10
Name WeaponCC: 'DMG Calc'!$B$4

Sheet DMG Calc
B1: Build 1 | C1: Build 2 | D1: Build 3 | E1: Build 4 | G1: Build 1 | H1: Build 2 | I1: Build 3 | J1: Build 4
A2: P.Atk | B2: 3715 | C2: 3715 | D2: 3715 | E2: 0
A3: M.Atk | B3: 0 | C3: 0 | D3: 0 | E3: 0
A4: Weapons Ability Potency (C.Ability) | B4: 17.97 | C4: 17.97 | D4: 17.97 | E4: 0
A5: Highwind Wpn C. Ability Potency | B5: 0.3 | C5: 0.3 | D5: 0.3 | E5: 0
A6: Sum of Elemental Potency from Materia | B6: 0 | C6: 0 | D6: 0 | E6: 0
A7: Damage Type | B7: Physical | C7: Physical | D7: Physical | E7: Magical
A8: R.Ability settings
A9: Ability Potency | B9: No Points | C9: No Points | D9: No Points | E9: No Points | G9: =VLOOKUP(B9,'Data Table'!$J$3:$K$10,2,FALSE) -> 0 | H9: =VLOOKUP(C9,'Data Table'!$J$3:$K$10,2,FALSE) -> 0 | I9: =VLOOKUP(D9,'Data Table'!$J$3:$K$10,2,FALSE) -> 0 | J9: =VLOOKUP(E9,'Data Table'!$J$3:$K$10,2,FALSE) -> 0
A10: Phys. Ability Potency | B10: Lv. 5 (35 Points) | C10: Lv. 5 (35 Points) | D10: Lv. 5 (35 Points) | E10: No Points | G10: =VLOOKUP(B10,'Data Table'!$J$15:$K$22,2,FALSE) -> 0.6 | H10: =VLOOKUP(C10,'Data Table'!$J$15:$K$22,2,FALSE) -> 0.6 | I10: =VLOOKUP(D10,'Data Table'!$J$15:$K$22,2,FALSE) -> 0.6 | J10: =VLOOKUP(E10,'Data Table'!$J$15:$K$22,2,FALSE) -> 0
A11: Mag. Ability Potency | B11: No Points | C11: No Points | D11: No Points | E11: No Points | G11: =VLOOKUP(B11,'Data Table'!$J$15:$K$22,2,FALSE) -> 0 | H11: =VLOOKUP(C11,'Data Table'!$J$15:$K$22,2,FALSE) -> 0 | I11: =VLOOKUP(D11,'Data Table'!$J$15:$K$22,2,FALSE) -> 0 | J11: =VLOOKUP(E11,'Data Table'!$J$15:$K$22,2,FALSE) -> 0
A12: Elemental Potency | B12: No Points | C12: No Points | D12: No Points | E12: No Points | G12: =VLOOKUP(B12,'Data Table'!$N$3:$O$13,2,FALSE) -> 0 | H12: =VLOOKUP(C12,'Data Table'!$N$3:$O$13,2,FALSE) -> 0 | I12: =VLOOKUP(D12,'Data Table'!$N$3:$O$13,2,FALSE) -> 0 | J12: =VLOOKUP(E12,'Data Table'!$N$3:$O$13,2,FALSE) -> 0
A13: Outfit/Gear/UW settings
A14: Outfit Ability (Arcanum, Mastery, Elements) | B14: 0.3 | C14: 0.3 | D14: 0.3 | E14: 0
A15: Outfit Ability Phys. Cmd. Stance Dmg | B15: 0 | C15: 0 | D15: 0 | E15: 0
A16: Outfit Ability Mag. Cmd. Stance Dmg | B16: 0 | C16: 0 | D16: 0 | E16: 0
A17: Boost Elemental Pot.(All Allies) | B17: 0.15 | C17: 0.15 | D17: 0.15 | E17: 0
A18: Memoria settings
A19: Memoria Elemental Potency | B19: 0 | C19: 0 | D19: 0 | E19: 0.2
A20: Memoria Phys. Ability Potency | B20: 0 | C20: 0 | D20: 0 | E20: 0
A21: Memoria Mag. Ability Potency | B21: 0 | C21: 0 | D21: 0 | E21: 0.15
A22: Memoria Species Potency | B22: 0 | C22: 0 | D22: 0 | E22: 0
A23: Interruption settings
A24: Interruption Sigil Damage Boost | B24: 0 | C24: 0 | D24: 0 | E24: 0
A25: Interruption R. Abilites | B25: 0 | C25: 0 | D25: 0 | E25: 0
A26: Interruption Mastery | B26: 0 | C26: 0 | D26: 0 | E26: 0
A27: Interruption Arcanum | B27: 0 | C27: 0 | D27: 0 | E27: 0
A28: Overspeed settings
A29: Overspeed Passive Elemental Potency | B29: 0.1 | C29: 0.1 | D29: 0.1 | E29: 0.1 | G29: =VLOOKUP(B29,'Data Table'!$B$15:$C$16,2,FALSE) -> 0.1 | H29: =VLOOKUP(C29,'Data Table'!$B$15:$C$16,2,FALSE) -> 0.1 | I29: =VLOOKUP(D29,'Data Table'!$B$15:$C$16,2,FALSE) -> 0.1 | J29: =VLOOKUP(E29,'Data Table'!$B$15:$C$16,2,FALSE) -> 0.1
A30: Overspeed Buff | B30: No OS | C30: No OS | D30: No OS | E30: No OS | G30: =VLOOKUP(B30,'Data Table'!$B$25:$C$35,2,FALSE) -> 0 | H30: =VLOOKUP(C30,'Data Table'!$B$25:$C$35,2,FALSE) -> 0 | I30: =VLOOKUP(D30,'Data Table'!$B$25:$C$35,2,FALSE) -> 0 | J30: =VLOOKUP(E30,'Data Table'!$B$25:$C$35,2,FALSE) -> 0
A31: Buff settings | K31: atlea
A32: P.Atk Buff | B32: No Buff | C32: No Buff | D32: No Buff | E32: No Buff | G32: =VLOOKUP(B32,'Data Table'!$F$3:$G$10,2,FALSE) -> 0 | H32: =VLOOKUP(C32,'Data Table'!$F$3:$G$10,2,FALSE) -> 0 | I32: =VLOOKUP(D32,'Data Table'!$F$3:$G$10,2,FALSE) -> 0 | J32: =VLOOKUP(E32,'Data Table'!$F$3:$G$10,2,FALSE) -> 0
A33: M.Atk Buff | B33: No Buff | C33: No Buff | D33: No Buff | E33: No Buff | G33: =VLOOKUP(B33,'Data Table'!$F$3:$G$10,2,FALSE) -> 0 | H33: =VLOOKUP(C33,'Data Table'!$F$3:$G$10,2,FALSE) -> 0 | I33: =VLOOKUP(D33,'Data Table'!$F$3:$G$10,2,FALSE) -> 0 | J33: =VLOOKUP(E33,'Data Table'!$F$3:$G$10,2,FALSE) -> 0
A34: Elemental Potency Up Buff | B34: No Elem. Pot. Buff | C34: No Elem. Pot. Buff | D34: No Elem. Pot. Buff | E34: No Elem. Pot. Buff | G34: =VLOOKUP(B34,'Data Table'!$F$15:$G$22,2,FALSE) -> 0 | H34: =VLOOKUP(C34,'Data Table'!$F$15:$G$22,2,FALSE) -> 0 | I34: =VLOOKUP(D34,'Data Table'!$F$15:$G$22,2,FALSE) -> 0 | J34: =VLOOKUP(E34,'Data Table'!$F$15:$G$22,2,FALSE) -> 0
A35: Exploit Weakness | B35: 0.4 | C35: 0.4 | D35: 0 | E35: 0
A36: Phys./Mag. Weapon C./U.C Buff | B36: 0.4 | C36: 0.4 | D36: 0 | E36: 0
A37: Elemental Weapon Boost C./U.C Buff | B37: 0.4 | C37: 0 | D37: 0 | E37: 0
A38: Amplification Phys./Mag. C. Abilitiy | B38: 0 | C38: 0 | D38: 0 | E38: 0
A39: Elemental Amplification | B39: 0 | C39: 0 | D39: 0 | E39: 0
A40: Phys./Mag. Bonus Additional Damage | B40: 0 | C40: 0.3 | D40: 0 | E40: 0
...

Sheet Dungeon Ranking Calc
D9: Variable Scores | G9: Fixed Scores
D11: Total Score | E11: 5783049 | G11: Item Usage | H11: 1434000
D12: - Score Buff 15% | E12: 0 | G12: Extra Bonus | H12: 120000 | M12: 135640
G13: Dungeon Clear | H13: 10000 | M13: 206356
D14: Score without Buff | E14: =E11+E12 -> 5783049 | G14: 1) | H14: =SUM(H11:H13) -> 1564000 | M14: 308685
G16: Battle Score | H16: 877875
D17: Check Result | G17: Speed Run Bonus | H17: 352700 | M17: 135640
D18: Total Score | E18: =H18+H14+H22 -> 5309692.5 | G18: 2) | H18: =SUM(H16:H17) -> 1230575 | M18: 206785
D19: 15% Score Buff | E19: 0
E20: =SUM(E18:E19) -> 5309692.5 | G20: Result 1) + 2) | H20: =H14+H18 -> 2794575
G22: Multi x 0.9 Boss Takedown Bonus | H22: =(H14+H18)*0.9 -> 2515117.5
G25: Total Score without Bonus | H25: =H20+H22 -> 5309692.5
G27: 15% Trance Bonus | H27: 0
G29: Dungeon Score | H29: =H25+H27 -> 5309692.5

Sheet Memoria EXP Table
B2: Memoria EXP
C5: Lv. | D5: Exp to Lv. Up | F5: x9 Runs / 180 Stamina | G5: Stamina | I5: x12 Runs / 180 Stamina | J5: Stamina
C6: 1 | D6: 4000 | F6: =D6/1800 -> 2.2222222 | G6: =F6*180 -> 400 | I6: =D6/2400 -> 1.6666667 | J6: =I6*180 -> 300 | M6: Memorial Shards EXP
C7: 2 | D7: 5000 | F7: =D7/1800 -> 2.7777778 | G7: =F7*180 -> 500 | I7: =D7/2400 -> 2.0833333 | J7: =I7*180 -> 375 | M7: Small | N7: 4
C8: 3 | D8: 6200 | F8: =D8/1800 -> 3.4444444 | G8: =F8*180 -> 620 | I8: =D8/2400 -> 2.5833333 | J8: =I8*180 -> 465 | M8: Medium | N8: 22.8
C9: 4 | D9: 7600 | F9: =D9/1800 -> 4.2222222 | G9: =F9*180 -> 760 | I9: =D9/2400 -> 3.1666667 | J9: =I9*180 -> 570 | M9: Large | N9: ?
C10: 5 | D10: 9500 | F10: =D10/1800 -> 5.2777778 | G10: =F10*180 -> 950 | I10: =D10/2400 -> 3.9583333 | J10: =I10*180 -> 712.5
C11: 6 | D11: 11700 | F11: =D11/1800 -> 6.5 | G11: =F11*180 -> 1170 | I11: =D11/2400 -> 4.875 | J11: =I11*180 -> 877.5
C12: 7 | D12: 14500 | F12: =D12/1800 -> 8.0555556 | G12: =F12*180 -> 1450 | I12: =D12/2400 -> 6.0416667 | J12: =I12*180 -> 1087.5
C13: 8 | D13: 18000 | F13: =D13/1800 -> 10 | G13: =F13*180 -> 1800 | I13: =D13/2400 -> 7.5 | J13: =I13*180 -> 1350
C14: 9 | D14: 23500 | F14: =D14/1800 -> 13.055556 | G14: =F14*180 -> 2350 | I14: =D14/2400 -> 9.7916667 | J14: =I14*180 -> 1762.5
C15: 10 | D15: 0 | F15: =D15/1800 -> 0 | G15: =F15*180 -> 0 | I15: =D15/2400 -> 0 | J15: =I15*180 -> 0
C16: Total | D16: =SUM(D6:D15) -> 100000 | F16: =SUM(F6:F15) -> 55.555556 | G16: =SUM(G6:G15) -> 10000 | I16: =SUM(I6:I15) -> 41.666667 | J16: =SUM(J6:J15) -> 7500
F17: Stamina Pots | G17: =G16/50 -> 200 | I17: Stamina Pots | J17: =J16/50 -> 150

Sheet GuildShop
O1: Level 4 | P1: Level 4 | Q1: Level 4 | R1: Level 4 | S1: Level 5 | T1: Level 4 | U1: Level 4 | V1: Level 4
G2: Level 1 | K2: Total | O2: 46198 | P2: 46228 | Q2: 46259 | R2: 46290 | S2: 46320 | T2: 46351 | U2: 46381 | V2: 46048
B3: Guild Points per Player | C3: Daily | D3: Weekly | E3: Monthly | H3: 1x | I3: Gr. Atk. Branding | J3: 2500 | K3: 2500 | N3: Held | O3: 0 | P3: =O6 -> 11500 | Q3: =P6 -> 23000 | R3: =Q6 -> 34500 | S3: =R6 -> 46000 | T3: =S6 -> 0 | U3: =T6 -> 11500 | V3: =U6 -> 23000
C4: 160 | D4: =C4*7 -> 1120 | E4: =C4*30 -> 4800 | H4: 1x | I4: Gr. Def. Branding | J4: 2500 | K4: 2500 | N4: Gain | O4: 50000 | P4: 50000 | Q4: 50000 | R4: 50000 | S4: 50000 | T4: 50000 | U4: 50000 | V4: 50000
B5: Guild Total | C5: =C4*30 -> 4800 | D5: =D4*30 -> 33600 | E5: =E4*30 -> 144000 | H5: 10x | I5: Atk. Branding | J5: 500 | K5: 5000 | N5: Used | O5: 38500 | P5: 38500 | Q5: 38500 | R5: 38500 | S5: 96000 | T5: 38500 | U5: 38500 | V5: 38500
H6: 10x | I6: Def. Branding | J6: 500 | K6: 5000 | N6: Left overs | O6: =O3+O4-O5 -> 11500 | P6: =P3+P4-P5 -> 23000 | Q6: =Q3+Q4-Q5 -> 34500 | R6: =R3+R4-R5 -> 46000 | S6: =S3+S4-S5 -> 0 | T6: =T3+T4-T5 -> 11500 | U6: =U3+U4-U5 -> 23000 | V6: =V3+V4-V5 -> 34500
B7: Guild EXP per Player | H7: 10x | I7: Draw Ticket | J7: 200 | K7: 2000
C8: 400 | D8: =C8*7 -> 2800 | E8: =C8*30 -> 12000 | H8: 100x | I8: Less. Atk. Branding | J8: 500 | K8: 50000
B9: Guild Total | C9: =C8*30 -> 12000 | D9: =D8*30 -> 84000 | E9: =E8*30 -> 360000 | H9: 100x | I9: Less. Def. Branding | J9: 500 | K9: 50000
K10: =SUM(K3:K9) -> 117000
B11: Level 1 > 2 | C11: 4000
B12: Level 2 > 3 | C12: 11000 | G12: Level 2
B13: Level 3 > 4 | C13: 55000 | D13: > | E13: =SUM(C11:C13) -> 70000 | H13: 1x | I13: Gr. Atk. Branding | J13: 1500 | K13: 1500
B14: Level 4 > 5 | C14: 130000 | H14: 1x | I14: Gr. Def. Branding | J14: 1500 | K14: 1500
C15: =SUM(C11:C14) -> 200000 | H15: 1x | I15: 5 Star Ticket | J15: 2500 | K15: 2500
K16: =SUM(K13:K15) -> 5500
G18: Level 3
H19: 1x | I19: 5 Star Ticket | J19: 1000 | K19: 1000
H20: 10x | I20: 4 Star Ticket | J20: 500 | K20: 5000
K21: =SUM(K18:K20) -> 6000
G23: Level 4
H24: 200x | I24: Stamina Tonic | J24: 50 | K24: 10000 | L24: =SUM(K3:K7,K13:K15,K19:K20,K24) -> 38500
K25: =SUM(K24) -> 10000
G27: Level 5
H28: 100x | I28: Atk. Branding | J28: 500 | K28: 50000 | L28: =S5-L24 -> 57500
H29: 100x | I29: Def. Branding | J29: 500 | K29: 50000
K30: =SUM(K28:K29) -> 100000
J32: Total | K32: =SUM(K10,K16,K21,K25,K30) -> 238500

Sheet Data Table
A3: Defence Debuff | B3: No Debuff | C3: 0 | E3: Offensiv Buffs | F3: No Buff | G3: 0 | I3: Ability Pot. | J3: No Points | K3: 0 | M3: Ele Pot. | N3: No Points | O3: 0
B4: Low | C4: 0.15 | F4: Low | G4: 0.1 | J4: Lv. 1 (1 Point) | K4: 0.03 | N4: Lv. 1 (1 Point) | O4: 0.06
B5: Mid | C5: 0.25 | F5: Mid | G5: 0.2 | J5: Lv. 2 (5 Points) | K5: 0.08 | N5: Lv. 2 (5 Points) | O5: 0.15
B6: High | C6: 0.35 | F6: High | G6: 0.3 | J6: Lv. 3 (15 Points) | K6: 0.15 | N6: Lv. 3 (15 Points) | O6: 0.25
B7: Extra High | C7: 0.45 | F7: Extra High | G7: 0.4 | J7: Lv. 4 (25 Points) | K7: 0.22 | N7: Lv. 4 (25 Points) | O7: 0.4
B8: Extreme High | C8: 0.55 | F8: Extreme High | G8: 0.5 | J8: Lv. 5 (35 Points) | K8: 0.3 | N8: Lv. 5 (35 Points) | O8: 0.55
F9: Extreme High+ | G9: 0.6 | J9: Lv. 6 (45 Points) | K9: 0.35 | N9: Lv. 6 (45 Points) | O9: 0.7
F10: Extreme High++ | G10: 0.7 | J10: Lv. 7 (55 Points) | K10: 0.4 | N10: Lv. 7 (55 Points) | O10: 0.85
N11: Lv. 8 (65 Points) | O11: 1
N12: Lv. 9 (80 Points) | O12: 1.1
N13: Lv. 10 (100 Points) | O13: 1.2
A15: OS Ele Pot | B15: 0 | C15: 0 | E15: Elemental Buff | F15: No Elem. Pot. Buff | G15: 0 | I15: Phys&Mag Pot | J15: No Points | K15: 0
B16: 0.1 | C16: 0.1 | F16: Low | G16: 0.1 | J16: Lv. 1 (1 Point) | K16: 0.05
F17: Mid | G17: 0.25 | J17: Lv. 2 (5 Points) | K17: 0.15
F18: High | G18: 0.4 | J18: Lv. 3 (15 Points) | K18: 0.3
F19: Extra High | G19: 0.6 | J19: Lv. 4 (25 Points) | K19: 0.45
F20: Extreme High | G20: 0.8 | J20: Lv. 5 (35 Points) | K20: 0.6
F21: Extreme High+ | G21: 1 | J21: Lv. 6 (45 Points) | K21: 0.7
F22: Extreme High++ | G22: 1.2 | J22: Lv. 7 (55 Points) | K22: 0.8
A25: OS Lv | B25: No OS | C25: 0 | E25: Elem. Ress Debuff | F25: No Elem. Res. Debuff | G25: 0
B26: OS Attacker Lv 1 | C26: 0 | F26: Low | G26: 0.15
B27: OS Attacker Lv 2 | C27: 0.05 | F27: Mid | G27: 0.3 | I27: Cmd Stance | J27: 0.5 | K27: 0.5
B28: OS Attacker Lv 3 | C28: 0.1 | F28: High | G28: 0.5 | J28: 0.65 | K28: 0.65
B29: OS Attacker Lv 4 | C29: 0.15 | F29: Extra High | G29: 0.75
B30: OS Attacker Lv 5 | C30: 0.2 | F30: Extreme High | G30: 1
B31: OS Supporter Lv 1 | C31: 0 | I31: Elem. Ability (All Allies)
B32: OS Supporter Lv 2 | C32: 0 | J32: No Pot. | K32: 0
B33: OS Supporter Lv 3 | C33: 0.05 | J33: Lv. 1 (1 Point) | K33: 0.05
B34: OS Supporter Lv 4 | C34: 0.1 | J34: Lv. 2 (5 Points) | K34: 0.1
B35: OS Supporter Lv 5 | C35: 0.1 | J35: Lv. 3 (15 Points) | K35: 0.15
B51: mag amp | G51: fire ampp
M53: 58297475
M54: 34978485
M55: 57187710
M56: 34312626
M57: =SUM(M53:M56) -> 184776296
B66: mag + fire amp | H66: no amp
M67: 99234133
M68: 59540479
M69: 16745308
...
